Workbook
Name CFTC_DATES: [1]Futures!$A$8:$A$312
Name COMDTY: OFFSET([1]Futures!$B$9,0,0,[1]Futures!$B$7)
Name COMM: OFFSET([1]Futures!$E$9,0,0,[1]Futures!$B$7)
Name commfo: OFFSET([1]Futures!$J$9,0,0,[1]Futures!$B$7)
Name DATES: OFFSET([1]Futures!$A$9,0,0,[1]Futures!$B$7)
Name indexes: Tickers!$G$2:$AZ$2
Name LIST: Tickers!$B$3:$B$56
Name MANAGED: OFFSET([1]Futures!$G$9,0,0,[1]Futures!$B$7)
Name managedfo: OFFSET([1]Futures!$L$9,0,0,[1]Futures!$B$7)
Name NONCOM: OFFSET([1]Futures!$D$9,0,0,[1]Futures!$B$7)
Name noncomfo: OFFSET([1]Futures!$I$9,0,0,[1]Futures!$B$7)
Name tag: Tickers!$A$2:$BK$58
Name ticker: Tickers!$A$2:$AP$57

Sheet Tickers
A1: 1 | B1: =A1+1 -> 2 | C1: =B1+1 -> 3 | D1: =C1+1 -> 4 | E1: =D1+1 -> 5 | F1: =E1+1 -> 6 | G1: =F1+1 -> 7 | H1: =G1+1 -> 8 | I1: =H1+1 -> 9 | ... AP1: =AO1+1 -> 42 | AQ1: 43 | AR1: =AQ1+1 -> 44 | AS1: =AR1+1 -> 45 | AT1: =AS1+1 -> 46 | AU1: =AT1+1 -> 47 | AV1: =AU1+1 -> 48 | AW1: =AV1+1 -> 49 | AX1: =AW1+1 -> 50 | AY1: =AX1+1 -> 51 | ... BJ1: =BI1+1 -> 62
A2: tag | B2: Comdty | C2: 1st Contract Price | D2: PX_LAST | E2: Unit | F2: Contract Size | G2: Non Comercial Long | H2: Non Comercial Short | I2: Non Comercial Spreading | J2: Commercial Long | K2: Commercial Short | L2: Total Long | M2: Total Short | N2: Open Interest | O2: Non Reportable Long | P2: Non Reportable Short | Q2: Managed Money Long | R2: Managed Money Short | S2: Producer Long | T2: Producer Short | U2: Swap Dealers Long | V2: Swap Dealers Short | W2: Swap Dealers Spreading | X2: Managed Money Spread | Y2: Other Reportables Long | Z2: Other Reportables Short | AA2: Other Reportables Spreading | AB2: Non Commercial Net Position | AC2: Supplemental Index Traders Long | AD2: Supplemental Index Traders Short | AE2: Non Comercial Long F+O | AF2: Non Comercial Short F+O | AG2: Non Comercial Spreading F+O | AH2: Commercial Long F+O | AI2: Commercial Short F+O | AJ2: Total Long F+O | AK2: Total ShortF+O | AL2: Open Interest F+O | AM2: Non Reportable Long F+O | AN2: Non Reportable Short F+O | AO2: Managed Money Long F+ O | AP2: Managed Money Short F+ O | AQ2: Managed Money Spreading F+O | AR2: Producer Long F+O | AS2: Producer Short F+O | AT2: Swap Dealers Long F+O | AU2: Swap Dealers Short F+O | AV2: Swap Dealers Spreading F+O | AW2: Other Reportables Long F+O | AX2: Other Reportables Short F+O | AY2: Other Reportables Spreading F+O | AZ2: Index Traders Open Interest | BA2: Supplemental Non Commercial Long F+O | BB2: Supplemental Non Commercial Short F+O | BC2: Supplemental Non Commercial Spreading F+O | BD2: Supplemental Non Commercial Net Position F+O | BE2: Supplemental Commercial Long F+O | BF2: Supplemental Commercial Short F+O | BG2: Supplemental Commercial Net Position F+O | BH2: Supplemental Non Reportable Long F+O | BI2: Supplemental Non Reportable Short F+O | BJ2: Supplemental Non Reportable Net Position F+O | BK2: TAG2
A3: 1 | B3: GRAIN - CBOT WHEAT | C3: W 1 Comdty | D3: =_xll.BDH(Tickers!$C3,"px_last",[1]Futures!$A$9,[1]Futures!$A$9,"days=all") -> #NAME? | E3: =_xll.BDP(C3,"QUOTE_UNITS") -> #NAME? | F3: =_xll.BDP(C3,"FUT_CONT_SIZE")/100 -> #NAME? | G3: CBT1WNCL Index | H3: CBT1WNCS Index | I3: CBT1WNCP Index | J3: CBT1WCOL Index | K3: CBT1WCOS Index | L3: CBT1WTLL Index | M3: CBT1WTLS Index | N3: CBT1WOIN Index | O3: CBT1WNRL Index | P3: CBT1WNRS Index | Q3: CFFDAMML Index | R3: CFFDAMMS Index | S3: CFFDAPML Index | T3: CFFDAPMS Index | U3: CFFDASWL Index | V3: CFFDASWS Index | W3: CFFDASWD Index | X3: CFFDAMMD Index | Y3: CFFDAORL Index | Z3: CFFDAORS Index | AA3: CFFDAORD Index | AB3: CBT1WNCN Index | AC3: CBTOTCIL Index | AD3: CBTOTCIS Index | AE3: CBTOWNCL Index | AF3: CBTOWNCS Index | AG3: CBTOWNCP Index | AH3: CBTOWCOL Index | AI3: CBTOWCOS Index | AJ3: CBTOWTLL Index | AK3: CBTOWTLS Index | AL3: CBTOWOIN Index | AM3: CBTOWNRL Index | AN3: CBTOWNRS Index | AO3: CFCDAMML Index | AP3: CFCDAMMS Index | AQ3: CFCDAMMD Index | AR3: CFCDAPML Index | AS3: CFCDAPMS Index | AT3: CFCDASWL Index | AU3: CFCDASWS Index | AV3: CFCDASWD Index | AW3: CFCDAORL Index | AX3: CFCDAORS Index | AY3: CFCDAORD Index | AZ3: CBTOWOIN Index | BA3: CBTOWNCL Index | BB3: CBTOWNCS Index | BC3: CBTOWNCP Index | BD3: CBTOWNCN Index | BE3: CBTOWCOL Index | BF3: CBTOWCOS Index | BG3: CBTOWCON Index | BH3: CBTOWNRL Index | BI3: CBTOWNRS Index | BJ3: CBTOWNRN Index | BK3: =A3 -> 1
A4: 2 | B4: GRAIN - KCB WHEAT | C4: KW1 Comdty | D4: =_xll.BDH(Tickers!$C4,"px_last",[1]Futures!$A$9,[1]Futures!$A$9,"days=all") -> #NAME? | E4: =_xll.BDP(C4,"QUOTE_UNITS") -> #NAME? | F4: =_xll.BDP(C4,"FUT_CONT_SIZE")/100 -> #NAME? | G4: KCBTWNCL Index | H4: KCBTWNCS Index | I4: KCBTWNCP Index | J4: KCBTWCOL Index | K4: KCBTWCOS Index | L4: KCBTWTLL Index | M4: KCBTWTLS Index | N4: KCBTWOIN Index | O4: KCBTWNRL Index | P4: KCBTWNRS Index | Q4: CFFDBMML Index | R4: CFFDBMMS Index | S4: CFFDBPML Index | T4: CFFDBPMS Index | U4: CFFDBSWL Index | V4: CFFDBSWS Index | W4: CFFDBSWD Index | X4: CFFDBMML Index | Y4: CFFDBORL Index | Z4: CFFDBORS Index | AA4: CFFDBORD Index | AB4: KCBTWNCN Index | AC4: KCBOTCIL Index | AD4: KCBOTCIS Index | AE4: KCBOWNCL Index | AF4: KCBOWNCS Index | AG4: KCBOWNCP Index | AH4: KCBOWCOL Index | AI4: KCBOWCOS Index | AJ4: KCBOWTLL Index | AK4: KCBOWTLS Index | AL4: KCBOWOIN Index | AM4: KCBOWNRL Index | AN4: KCBOWNRS Index | AO4: CFCDBMML Index | AP4: CFCDBMMS Index | AQ4: CFCDBMMD Index | AR4: CFCDBPML Index | AS4: CFCDBPMS Index | AT4: CFCDBSWL Index | AU4: CFCDBSWS Index | AV4: CFCDBSWD Index | AW4: CFCDBORL Index | AX4: CFCDBORS Index | AY4: CFCDBORD Index | AZ4: KCBOWOIN Index | BA4: KCBOWNCL Index | BB4: KCBOWNCS Index | BC4: KCBOWNCP Index | BD4: KCBOWNCN Index | BE4: KCBOWCOL Index | BF4: KCBOWCOS Index | BG4: KCBOWCON Index | BH4: KCBOWNRL Index | BI4: KCBOWNRS Index | BJ4: KCBOWNRN Index | BK4: =A4 -> 2
A5: 3 | B5: GRAIN - MGE WHEAT | C5: MW1 Comdty | D5: =_xll.BDH(Tickers!$C5,"px_last",[1]Futures!$A$9,[1]Futures!$A$9,"days=all") -> #NAME? | E5: =_xll.BDP(C5,"QUOTE_UNITS") -> #NAME? | F5: =_xll.BDP(C5,"FUT_CONT_SIZE")/100 -> #NAME? | G5: MGE1WNCL Index | H5: MGE1WNCS Index | I5: MGE1WNCP Index | J5: MGE1WCOL Index | K5: MGE1WCOS Index | L5: MGE1WTLL Index | M5: MGE1WTLS Index | N5: MGE1WOIN Index | O5: MGE1WNRL Index | P5: MGE1WNRS Index | Q5: DFU1AMML Index | R5: DFU1AMMS Index | S5: DFU1APML Index | T5: DFU1APMS Index | U5: DFU1ASWL Index | V5: DFU1ASWS Index | W5: DFU1ASWD Index | X5: DFU1AMMD Index | Y5: DFU1AORL Index | Z5: DFU1AORS Index | AA5: DFU1AORD Index | AB5: MGE1WNCN Index | AE5: MGEOWNCL Index | AF5: MGEOWNCS Index | AG5: MGEOWNCP Index | AH5: MGEOWCOL Index | AI5: MGEOWCOS Index | AJ5: MGEOWTLL Index | AK5: MGEOWTLS Index | AL5: MGEOWOIN Index | AM5: MGEOWNRL Index | AN5: MGEOWNRS Index | AO5: DCO1AMML Index | AP5: DCO1AMMS Index | AQ5: DCO1AMMD Index | AR5: DCO1APML Index | AS5: DCO1APMS Index | AT5: DCO1ASWL Index | AU5: DCO1ASWS Index | AV5: DCO1ASWD Index | AW5: DCO1AORL Index | AX5: DCO1AORS Index | AY5: DCO1AORD Index | BK5: =A5 -> 3
A6: 4 | B6: GRAIN - CBOT SOYBEAN | C6: S 1 Comdty | D6: =_xll.BDH(Tickers!$C6,"px_last",[1]Futures!$A$9,[1]Futures!$A$9,"days=all") -> #NAME? | E6: =_xll.BDP(C6,"QUOTE_UNITS") -> #NAME? | F6: =_xll.BDP(C6,"FUT_CONT_SIZE")/100 -> #NAME? | G6: CBT1SNCL Index | H6: CBT1SNCS Index | I6: CBT1SNCP Index | J6: CBT1SCOL Index | K6: CBT1SCOS Index | L6: CBT1STLL Index | M6: CBT1STLS Index | N6: CBT1SOIN Index | O6: CBT1SNRL Index | P6: CBT1SNRS Index | Q6: CFFDGMML Index | R6: CFFDGMMS Index | S6: CFFDGPML Index | T6: CFFDGPMS Index | U6: CFFDGSWL Index | V6: CFFDGSWS Index | W6: CFFDGSWD Index | X6: CFFDGMMD Index | Y6: CFFDGORL Index | Z6: CFFDGORS Index | AA6: CFFDGORD Index | AB6: CBT1SNCN Index | AC6: CBTOSCIL Index | AD6: CBTOSCIS Index | AE6: CBTOSNCL Index | AF6: CBTOSNCS Index | AG6: CBTOSNCP Index | AH6: CBTOSCOL Index | AI6: CBTOSCOS Index | AJ6: CBTOSTLL Index | AK6: CBTOSTLS Index | AL6: CBTOSOIN Index | AM6: CBTOSNRL Index | AN6: CBTOSNRS Index | AO6: CFCDGMML Index | AP6: CFCDGMMS Index | AQ6: CFCDGMMD Index | AR6: CFCDGPML Index | AS6: CFCDGPMS Index | AT6: CFCDGSWL Index | AU6: CFCDGSWS Index | AV6: CFCDGSWD Index | AW6: CFCDGORL Index | AX6: CFCDGORS Index | AY6: CFCDGORD Index | AZ6: CBTOSOIN Index | BA6: CBTOSNCL Index | BB6: CBTOSNCS Index | BC6: CBTOSNCP Index | BD6: CBTOSNCN Index | BE6: CBTOSCOL Index | BF6: CBTOSCOS Index | BG6: CBTOSCON Index | BH6: CBTOSNRL Index | BI6: CBTOSNRS Index | BJ6: CBTOSNRN Index | BK6: =A6 -> 4
A7: 5 | B7: GRAIN - CBOT CORN | C7: C 1 Comdty | D7: =_xll.BDH(Tickers!$C7,"px_last",[1]Futures!$A$9,[1]Futures!$A$9,"days=all") -> #NAME? | E7: =_xll.BDP(C7,"QUOTE_UNITS") -> #NAME? | F7: =_xll.BDP(C7,"FUT_CONT_SIZE")/100 -> #NAME? | G7: CBT1CNCL Index | H7: CBT1CNCS Index | I7: CBT1CNCP Index | J7: CBT1CCOL Index | K7: CBT1CCOS Index | L7: CBT1CTLL Index | M7: CBT1CTLS Index | N7: CBT1COIN Index | O7: CBT1CNRL Index | P7: CBT1CNRS Index | Q7: CFFDCMML Index | R7: CFFDCMMS Index | S7: CFFDCPML Index | T7: CFFDCPMS Index | U7: CFFDCSWL Index | V7: CFFDCSWS Index | W7: CFFDCSWD Index | X7: CFFDCMMD Index | Y7: CFFDCORL Index | Z7: CFFDCORS Index | AA7: CFFDCORD Index | AB7: CBT1CNCN Index | AC7: CBTOCCIL Index | AD7: CBTOCCIS Index | AE7: CBTOCNCL Index | AF7: CBTOCNCS Index | AG7: CBTOCNCP Index | AH7: CBTOCCOL Index | AI7: CBTOCCOS Index | AJ7: CBTOCTLL Index | AK7: CBTOCTLS Index | AL7: CBTOCOIN Index | AM7: CBTOCNRL Index | AN7: CBTOCNRS Index | AO7: CFCDCMML Index | AP7: CFCDCMMS Index | AQ7: CFCDCMMD Index | AR7: CFCDCPML Index | AS7: CFCDCPMS Index | AT7: CFCDCSWL Index | AU7: CFCDCSWS Index | AV7: CFCDCSWD Index | AW7: CFCDCORL Index | AX7: CFCDCORS Index | AY7: CFCDCORD Index | AZ7: CBTOCOIN Index | BA7: CBTOCNCL Index | BB7: CBTOCNCS Index | BC7: CBTOCNCP Index | BD7: CBTOCNCN Index | BE7: CBTOCCOL Index | BF7: CBTOCCOS Index | BG7: CBTOCCON Index | BH7: CBTOCNRL Index | BI7: CBTOCNRS Index | BJ7: CBTOCNRN Index | BK7: =A7 -> 5
A8: 6 | B8: GRAIN - CBOT SOYBEAN OIL | C8: BO1 Comdty | D8: =_xll.BDH(Tickers!$C8,"px_last",[1]Futures!$A$9,[1]Futures!$A$9,"days=all") -> #NAME? | E8: =_xll.BDP(C8,"QUOTE_UNITS") -> #NAME? | F8: =_xll.BDP(C8,"FUT_CONT_SIZE")/100 -> #NAME? | G8: CBT2SNCL Index | H8: CBT2SNCS Index | I8: CBT2SNCP Index | J8: CBT2SCOL Index | K8: CBT2SCOS Index | L8: CBT2STLL Index | M8: CBT2STLS Index | N8: CBT2SOIN Index | O8: CBT2SNRL Index | P8: CBT2SNRS Index | Q8: CFFDHMML Index | R8: CFFDHMMS Index | S8: CFFDHPML Index | T8: CFFDHPMS Index | U8: CFFDHSWL Index | V8: CFFDHSWS Index | W8: CFFDHSWD Index | X8: CFFDHMMD Index | Y8: CFFDHORL Index | Z8: CFFDHORS Index | AA8: CFFDHORD Index | AB8: CBT2SNCN Index | AC8: CBTPOCIL Index | AD8: CBTPOCIS Index | AE8: CBTPSNCL Index | AF8: CBTPSNCS Index | AG8: CBTPSNCP Index | AH8: CBTPSCOL Index | AI8: CBTPSCOS Index | AJ8: CBTPSTLL Index | AK8: CBTPSTLS Index | AL8: CBTPSOIN Index | AM8: CBTPSNRL Index | AN8: CBTPSNRS Index | AO8: CFCDHMML Index | AP8: CFCDHMMS Index | AQ8: CFCDHMMD Index | AR8: CFCDHPML Index | AS8: CFCDHPMS Index | AT8: CFCDHSWL Index | AU8: CFCDHSWS Index | AV8: CFCDHSWD Index | AW8: CFCDHORL Index | AX8: CFCDHORS Index | AY8: CFCDHORD Index | AZ8: CBTPSOIN Index | BA8: CBT2SNCL Index | BB8: CBT2SNCS Index | BC8: CBT2SNCP Index | BD8: CBT2SNCN Index | BE8: CBT2SCOL Index | BF8: CBT2SCOS Index | BG8: CBT2SCON Index | BH8: CBT2SNRL Index | BI8: CBT2SNRS Index | BJ8: CBT2SNRN Index | BK8: =A8 -> 6
A9: 7 | B9: GRAIN - CBOT SOYBEAN MEAL | C9: SM1 Comdty | D9: =_xll.BDH(Tickers!$C9,"px_last",[1]Futures!$A$9,[1]Futures!$A$9,"days=all") -> #NAME? | E9: =_xll.BDP(C9,"QUOTE_UNITS") -> #NAME? | F9: =_xll.BDP(C9,"FUT_CONT_SIZE") -> #NAME? | G9: CBT3SNCL Index | H9: CBT3SNCS Index | I9: CBT3SNCP Index | J9: CBT3SCOL Index | K9: CBT3SCOS Index | L9: CBT3STLL Index | M9: CBT3STLS Index | N9: CBT3SOIN index | O9: CBT3SNRL Index | P9: CBT3SNRS Index | Q9: CFFDIMML Index | R9: CFFDIMMS Index | S9: CFFDIPML Index | T9: CFFDIPMS Index | U9: CFFDISWL Index | V9: CFFDISWS Index | W9: CFFDISWD Index | X9: CFFDIMMD Index | Y9: CFFDIORL Index | Z9: CFFDIORS Index | AA9: CFFDIORD Index | AB9: CBT3SNCN Index | AE9: CBTTSNCL Index | AF9: CBTTSNCS Index | AG9: CBTTSNCP Index | AH9: CBTTSCOL Index | AI9: CBTTSCOS Index | AJ9: CBTTSTLL Index | AK9: CBTTSTLS Index | AL9: CBTTSOIN Index | AM9: CBTTSNRL Index | AN9: CBTTSNRS Index | AO9: CFCDIMML Index | AP9: CFCDIMMS Index | AQ9: CFCDIMMD Index | AR9: CFCDIPML Index | AS9: CFCDIPMS Index | AT9: CFCDISWL Index | AU9: CFCDISWS Index | AV9: CFCDISWD Index | AW9: CFCDIORL Index | AX9: CFCDIORS Index | AY9: CFCDIORD Index | BK9: =A9 -> 7
A10: 8 | B10: LIVESTOCK - CME FEEDER CATTLE | C10: FC1 Comdty | D10: =_xll.BDH(Tickers!$C10,"px_last",[1]Futures!$A$9,[1]Futures!$A$9,"days=all") -> #NAME? | E10: =_xll.BDP(C10,"QUOTE_UNITS") -> #NAME? | F10: =_xll.BDP(C10,"FUT_CONT_SIZE")/100 -> #NAME? | G10: CME1FNCL Index | H10: CME1FNCS Index | I10: CME1FNCP Index | J10: CME1FCOL Index | K10: CME1FCOS Index | L10: CME1FTLL Index | M10: CME1FTLS Index | N10: CME1FOIN Index | O10: CME1FNRL Index | P10: CME1FNRS Index | Q10: CFFDFMML Index | R10: CFFDFMMS Index | S10: CFFDFPML Index | T10: CFFDFPMS Index | U10: CFFDFSWL Index | V10: CFFDFSWS Index | W10: CFFDFSWD Index | X10: CFFDFMMD Index | Y10: CFFDFORL Index | Z10: CFFDFORS Index | AA10: CFFDFORD Index | AB10: CME1FNCN Index | AC10: CMEOFCIL Index | AD10: CMEOFCIS Index | AE10: CMEOFNCL Index | AF10: CMEOFNCS Index | AG10: CMEOFNCP Index | AH10: CMEOFCOL Index | AI10: CMEOFCOS Index | AJ10: CMEOFTLL Index | AK10: CMEOFTLS Index | AL10: CMEOFOIN Index | AM10: CMEOFNRL Index | AN10: CMEOFNRS Index | AO10: CFCDFMML Index | AP10: CFCDFMMS Index | AQ10: CFCDFMMD Index | AR10: CFCDFPML Index | AS10: CFCDFPMS Index | AT10: CFCDFSWL Index | AU10: CFCDFSWS Index | AV10: CFCDFSWD Index | AW10: CFCDFORL Index | AX10: CFCDFORS Index | AY10: CFCDFORD Index | AZ10: CMEOFOIN Index | BA10: CMEOFNCL Index | BB10: CMEOFNCS Index | BC10: CMEOFNCP Index | BD10: CMEOFNCN Index | BE10: CMEOFCOL Index | BF10: CMEOFCOS Index | BG10: CMEOFCON Index | BH10: CMEOFNRL Index | BI10: CMEOFNRS Index | BJ10: CMEOFNRN Index | BK10: =A10 -> 8
A11: 9 | B11: LIVESTOCK-CME LEAN HOGS | C11: LH1 Comdty | D11: =_xll.BDH(Tickers!$C11,"px_last",[1]Futures!$A$9,[1]Futures!$A$9,"days=all") -> #NAME? | E11: =_xll.BDP(C11,"QUOTE_UNITS") -> #NAME? | F11: =_xll.BDP(C11,"FUT_CONT_SIZE")/100 -> #NAME? | G11: CME3HNCL Index | H11: CME3HNCS Index | I11: CME3HNCP Index | J11: CME3HCOL Index | K11: CME3HCOS Index | L11: CME3HTLL Index | M11: CME3HTLS Index | N11: CME3HOIN Index | O11: CME3HNRL Index | P11: CME3HNRS Index | Q11: CFFDDMML Index | R11: CFFDDMMS Index | S11: CFFDDPML Index | T11: CFFDDPMS Index | U11: CFFDDSWL Index | V11: CFFDDSWS Index | W11: CFFDDSWD Index | X11: CFFDDMMD Index | Y11: CFFDDORL Index | Z11: CFFDDORS Index | AA11: CFFDDORD Index | AB11: CME3HNCN Index | AC11: CMEOHCIL Index | AD11: CMEOHCIS Index | AE11: CMEOHNCL Index | AF11: CMEOHNCS Index | AG11: CMEOHNCP Index | AH11: CMEOHCOL Index | AI11: CMEOHCOS Index | AJ11: CMEOHTLL Index | AK11: CMEOHTLS Index | AL11: CMEOHOIN Index | AM11: CMEOHNRL Index | AN11: CMEOHNRS Index | AO11: CFCDDMML Index | AP11: CFCDDMMS Index | AQ11: CFCDDMMD Index | AR11: CFCDDPML Index | AS11: CFCDDPMS Index | AT11: CFCDDSWL Index | AU11: CFCDDSWS Index | AV11: CFCDDSWD Index | AW11: CFCDDORL Index | AX11: CFCDDORS Index | AY11: CFCDDORD Index | AZ11: CMEOHOIN Index | BA11: CMEOHNCL Index | BB11: CMEOHNCS Index | BC11: CMEOHNCP Index | BD11: CMEOHNCN Index | BE11: CMEOHCOL Index | BF11: CMEOHCOS Index | BG11: CMEOHCON Index | BH11: CMEOHNRL Index | BI11: CMEOHNRS Index | BJ11: CMEOHNRN Index | BK11: =A11 -> 9
A12: 10 | B12: LIVESTOCK - CME LIVE CATTLE | C12: LC1 Comdty | D12: =_xll.BDH(Tickers!$C12,"px_last",[1]Futures!$A$9,[1]Futures!$A$9,"days=all") -> #NAME? | E12: =_xll.BDP(C12,"QUOTE_UNITS") -> #NAME? | F12: =_xll.BDP(C12,"FUT_CONT_SIZE")/100 -> #NAME? | G12: CME1LNCL Index | H12: CME1LNCS Index | I12: CME1LNCP Index | J12: CME1LCOL Index | K12: CME1LCOS Index | L12: CME1LTLL Index | M12: CME1LTLS Index | N12: CME1LOIN Index | O12: CME1LNRL Index | P12: CME1LNRS Index | Q12: CFFDEMML Index | R12: CFFDEMMS Index | S12: CFFDEPML Index | T12: CFFDEPMS Index | U12: CFFDESWL Index | V12: CFFDESWS Index | W12: CFFDESWD Index | X12: CFFDEMMD Index | Y12: CFFDEORL Index | Z12: CFFDEORS Index | AA12: CFFDEORD Index | AB12: CME1LNCN Index | AC12: CMEOLCIL Index | AD12: CMEOLCIS Index | AE12: CMEOLNCL Index | AF12: CMEOLNCS Index | AG12: CMEOLNCP Index | AH12: CMEOLCOL Index | AI12: CMEOLCOS Index | AJ12: CMEOLTLL Index | AK12: CMEOLTLS Index | AL12: CMEOLOIN Index | AM12: CMEOLNRL Index | AN12: CMEOLNRS Index | AO12: CFCDEMML Index | AP12: CFCDEMMS Index | AQ12: CFCDEMMD Index | AR12: CFCDEPML Index | AS12: CFCDEPMS Index | AT12: CFCDESWL Index | AU12: CFCDESWS Index | AV12: CFCDESWD Index | AW12: CFCDEORL Index | AX12: CFCDEORS Index | AY12: CFCDEORD Index | AZ12: CMEOLOIN Index | BA12: CMEOLNCL Index | BB12: CMEOLNCS Index | BC12: CMEOLNCP Index | BD12: CMEOLNCN Index | BE12: CMEOLCOL Index | BF12: CMEOLCOS Index | BG12: CMEOLCON Index | BH12: CMEOLNRL Index | BI12: CMEOLNRS Index | BJ12: CMEOLNRN Index | BK12: =A12 -> 10
A13: 11 | B13: FOODSTUFF - CME MILK (class III) | C13: DA1 comdty | D13: =_xll.BDH(Tickers!$C13,"px_last",[1]Futures!$A$9,[1]Futures!$A$9,"days=all") -> #NAME? | E13: USD/cwt | F13: =_xll.BDP(C13,"FUT_CONT_SIZE") -> #NAME? | G13: CME4MNCL Index | H13: CME4MNCS Index | I13: CME4MNCP Index | J13: CME4MCOL Index | K13: CME4MCOS Index | L13: CME4MTLL Index | M13: CME4MTLS Index | N13: CME4MOIN Index | O13: CME4MNRL Index | P13: CME4MNRS Index | Q13: DFU2JMML Index | R13: DFU2JMMS Index | S13: DFU2JPML Index | T13: DFU2JPMS Index | U13: DFU2JSWL Index | V13: DFU2JSWS Index | W13: DFU2JSWD Index | X13: DFU2JMMD Index | Y13: DFU2JORL Index | Z13: DFU2JORS Index | AA13: DFU2JORD Index | AB13: CME4MNCN Index | AE13: CMEOMNCL Index | AF13: CMEOMNCS Index | AG13: CMEOMNCP Index | AH13: CMEOMCOL Index | AI13: CMEOMCOS Index | AJ13: CMEOMTLL Index | AK13: CMEOMTLS Index | AL13: CMEOMOIN Index | AM13: CMEOMNRL Index | AN13: CMEOMNRS Index | AO13: DCO2JMML Index | AP13: DCO2JMMS Index | AQ13: DCO2JMMD Index | AR13: DCO2JPML Index | AS13: DCO2JPMS Index | AT13: DCO2JSWL Index | AU13: DCO2JSWS Index | AV13: DCO2JSWD Index | AW13: DCO2JORL Index | AX13: DCO2JORS Index | AY13: DCO2JORD Index | BK13: =A13 -> 11
A14: 12 | B14: FOODSTUFF - CME BUTTER (Grade AA) | C14: v61 comdty | D14: =_xll.BDH(Tickers!$C14,"px_last",[1]Futures!$A$9,[1]Futures!$A$9,"days=all") -> #NAME? | E14: USd/lb | F14: =_xll.BDP(C14,"FUT_CONT_SIZE")/100 -> #NAME? | G14: CCBFTNCL Index | H14: CCBFTNCS Index | I14: CCBFTNCP Index | J14: CCBFTCOL Index | K14: CCBFTCOS Index | L14: CCBFTTLL Index | M14: CCBFTTLS Index | N14: CCBFTOIN Index | O14: CCBFTNRL Index | P14: CCBFTNRS Index | Q14: CMB1AMML Index | R14: CMB1AMMS Index | S14: CMB1APML Index | T14: CMB1APMS Index | U14: CMB1ASWL Index | V14: CMB1ASWS Index | W14: CMB1ASWD Index | X14: CMB1AMMD Index | Y14: CMB1AORL Index | Z14: CMB1AORS Index | AA14: CMB1AORD Index | AB14: CCBFTNCN Index | AE14: CCBCTNCL Index | AF14: CCBCTNCS Index | AG14: CCBCTNCP Index | AH14: CCBCTCOL Index | AI14: CCBCTCOS Index | AJ14: CCBCTTLL Index | AK14: CCBCTTLS Index | AL14: CCBCTOIN Index | AM14: CCBCTNRL Index | AN14: CCBCTNRS Index | AO14: CMBCAMML Index | AP14: CMBCAMMS Index | AQ14: CMBCAMMD Index | AR14: CMBCAPML Index | AS14: CMBCAPMS Index | AT14: CMBCASWL Index | AU14: CMBCASWS Index | AV14: CMBCASWD Index | AW14: CMBCAORL Index | AX14: CMBCAORS Index | AY14: CMBCAORD Index | BK14: =A14 -> 12
A15: 13 | B15: OIL - NYM CRUDE OIL | C15: CL1 Comdty | D15: =_xll.BDH(Tickers!$C15,"px_last",[1]Futures!$A$9,[1]Futures!$A$9,"days=all") -> #NAME? | E15: =_xll.BDP(C15,"QUOTE_UNITS") -> #NAME? | F15: =_xll.BDP(C15,"FUT_CONT_SIZE") -> #NAME? | G15: NYM1CNCL Index | H15: NYM1CNCS Index | I15: NYM1CNCP Index | J15: NYM1CCOL Index | K15: NYM1CCOS Index | L15: NYM1CTLL Index | M15: NYM1CTLS Index | N15: NYM1COIN Index | O15: NYM1CNRL Index | P15: NYM1CNRS Index | Q15: CFFDQMML Index | R15: CFFDQMMS Index | S15: CFFDQPML Index | T15: CFFDQPMS Index | U15: CFFDQSWL Index | V15: CFFDQSWS Index | W15: CFFDQSWD Index | X15: CFFDQMMD Index | Y15: CFFDQORL Index | Z15: CFFDQORS Index | AA15: CFFDQORD Index | AB15: NYM1CNCN Index | AE15: NYMOCNCL Index | AF15: NYMOCNCS Index | AG15: NYMOCNCP Index | AH15: NYMOCCOL Index | AI15: NYMOCCOS Index | AJ15: NYMOCTLL Index | AK15: NYMOCTLS Index | AL15: NYMOCOIN Index | AM15: NYMOCNRL Index | AN15: NYMOCNRS Index | AO15: CFCDQMML Index | AP15: CFCDQMMS Index | AQ15: CFCDQMMD Index | AR15: CFCDQPML Index | AS15: CFCDQPMS Index | AT15: CFCDQSWL Index | AU15: CFCDQSWS Index | AV15: CFCDQSWD Index | AW15: CFCDQORL Index | AX15: CFCDQORS Index | AY15: CFCDQORD Index | BK15: =A15 -> 13
A16: 14 | B16: OIL - NYM GASOLINE RBOB | C16: XB1 Comdty | D16: =_xll.BDH(Tickers!$C16,"px_last",[1]Futures!$A$9,[1]Futures!$A$9,"days=all") -> #NAME? | E16: =_xll.BDP(C16,"QUOTE_UNITS") -> #NAME? | F16: =_xll.BDP(C16,"FUT_CONT_SIZE")/100 -> #NAME? | G16: NYM2XNCL Index | H16: NYM2XNCS Index | I16: NYM2XNCP Index | J16: NYM2XCOL Index | K16: NYM2XCOS Index | L16: NYM2XTLL Index | M16: NYM2XTLS Index | N16: NYM2XOIN Index | O16: NYM2XNRL Index | P16: NYM2XNRS Index | Q16: CFFDRMML Index | R16: CFFDRMMS Index | S16: CFFDRPML Index | T16: CFFDRPMS Index | U16: CFFDRSWL Index | V16: CFFDRSWS Index | W16: CFFDRSWD Index | X16: CFFDRMMD Index | Y16: CFFDRORL Index | Z16: CFFDRORS Index | AA16: CFFDRORD Index | AB16: NYM2XNCN Index | AE16: NYMOXNCL Index | AF16: NYMOXNCS Index | AG16: NYMOXNCP Index | AH16: NYMOXCOL Index | AI16: NYMOXCOS Index | AJ16: NYMOXTLL Index | AK16: NYMOXTLS Index | AL16: NYMOXOIN Index | AM16: NYMOXNRL Index | AN16: NYMOXNRS Index | AO16: CFCDRMML Index | AP16: CFCDRMMS Index | AQ16: CFCDRMMD Index | AR16: CFCDRPML Index | AS16: CFCDRPMS Index | AT16: CFCDRSWL Index | AU16: CFCDRSWS Index | AV16: CFCDRSWD Index | AW16: CFCDRORL Index | AX16: CFCDRORS Index | AY16: CFCDRORD Index | BK16: =A16 -> 14
A17: 15 | B17: OIL - NYM NATURAL GAS | C17: NG1 Comdty | D17: =_xll.BDH(Tickers!$C17,"px_last",[1]Futures!$A$9,[1]Futures!$A$9,"days=all") -> #NAME? | E17: =_xll.BDP(C17,"QUOTE_UNITS") -> #NAME? | F17: =_xll.BDP(C17,"FUT_CONT_SIZE") -> #NAME? | G17: NYM1NNCL Index | H17: NYM1NNCS Index | I17: NYM1NNCP Index | J17: NYM1NCOL Index | K17: NYM1NCOS Index | L17: NYM1NTLL Index | M17: NYM1NTLS Index | N17: NYM1NOIN Index | O17: NYM1NNRL Index | P17: NYM1NNRS Index | Q17: CFFDOMML Index | R17: CFFDOMMS Index | S17: CFFDOPML Index | T17: CFFDOPMS Index | U17: CFFDOSWL Index | V17: CFFDOSWS Index | W17: CFFDOSWD Index | X17: CFFDOMMD Index | Y17: CFFDOORL Index | Z17: CFFDOORS Index | AA17: CFFDOORD Index | AB17: NYM1NNCN Index | AE17: NYMONNCL Index | AF17: NYMONNCS Index | AG17: NYMONNCP Index | AH17: NYMONCOL Index | AI17: NYMONCOS Index | AJ17: NYMONTLL Index | AK17: NYMONTLS Index | AL17: NYMONOIN Index | AM17: NYMONNRL Index | AN17: NYMONNRS Index | AO17: CFCDOMML Index | AP17: CFCDOMMS Index | AQ17: CFCDOMMD Index | AR17: CFCDOPML Index | AS17: CFCDOPMS Index | AT17: CFCDOSWL Index | AU17: CFCDOSWS Index | AV17: CFCDOSWD Index | AW17: CFCDOORL Index | AX17: CFCDOORS Index | AY17: CFCDOORD Index | BK17: =A17 -> 15
A18: 16 | B18: OIL - NYM PROPANE | C18: BAP1 Comdty | D18: =_xll.BDH(Tickers!$C18,"px_last",[1]Futures!$A$9,[1]Futures!$A$9,"days=all") -> #NAME? | E18: =_xll.BDP(C18,"QUOTE_UNITS") -> #NAME? | F18: =_xll.BDP(C18,"FUT_CONT_SIZE") -> #NAME? | G18: CFF2ZNCL Index | H18: CFF2ZNCS Index | I18: CFF2ZNCP Index | J18: CFF2ZCOL Index | K18: CFF2ZCOS Index | L18: CFF2ZTLL Index | M18: CFF2ZTLS Index | N18: CFF2ZOIN Index | O18: CFF2ZNRL Index | P18: CFF2ZNRS Index | Q18: DFU3EMML Index | R18: DFU3EMMS Index | S18: DFU3EPML Index | T18: DFU3EPMS Index | U18: DFU3ESWL Index | V18: DFU3ESWS Index | W18: DFU3ESWD Index | X18: DFU3EMMD Index | Y18: DFU3EORL Index | Z18: DFU3EORS Index | AA18: DFU3EORD Index | AB18: CFF2ZNCN Index | AE18: CFO2ZNCL Index | AF18: CFO2ZNCS Index | AG18: CFO2ZNCP Index | AH18: CFO2ZCOL Index | AI18: CFO2ZCOS Index | AJ18: CFO2ZTLL Index | AK18: CFO2ZTLS Index | AL18: CFO2ZOIN Index | AM18: CFO2ZNRL Index | AN18: CFO2ZNRS Index | AO18: DCO3EMML Index | AP18: DCO3EMMS Index | AQ18: DCO3EMMD Index | AR18: DCO3EPML Index | AS18: DCO3EPMS Index | AT18: DCO3ESWL Index | AU18: DCO3ESWS Index | AV18: DCO3ESWD Index | AW18: DCO3EORL Index | AX18: DCO3EORS Index | AY18: DCO3EORD Index | BK18: =A18 -> 16
A19: 17 | B19: OIL- NYM ETHANE | C19: CAP1 Comdty | D19: =_xll.BDH(Tickers!$C19,"px_last",[1]Futures!$A$9,[1]Futures!$A$9,"days=all") -> #NAME? | E19: =_xll.BDP(C19,"QUOTE_UNITS") -> #NAME? | F19: =_xll.BDP(C19,"FUT_CONT_SIZE") -> #NAME? | G19: CFF3ANCL Index | H19: CFF3ANCS Index | I19: CFF3ANCP Index | J19: CFF3ACOL Index | K19: CFF3ACOS Index | L19: CFF3ATLL Index | M19: CFF3ATLS Index | N19: CFF3AOIN Index | O19: CFF3ANRL Index | P19: CFF3ANRS Index | Q19: DFU3FMML Index | R19: DFU3FMMS Index | S19: DFU3FPML Index | T19: DFU3FPMS Index | U19: DFU3FSWL Index | V19: DFU3FSWS Index | W19: DFU3FSWD Index | X19: DFU3FMMD Index | Y19: DFU3FORL Index | Z19: DFU3FORS Index | AA19: DFU3FORD Index | AB19: CFF3ANCN Index | AE19: CFO3ANCL Index | AF19: CFO3ANCS Index | AG19: CFO3ANCP Index | AH19: CFO3ACOL Index | AI19: CFO3ACOS Index | AJ19: CFO3ATLL Index | AK19: CFO3ATLS Index | AL19: CFO3AOIN Index | AM19: CFO3ANRL Index | AN19: CFO3ANRS Index | AO19: DCO3FMML Index | AP19: DCO3FMMS Index | AQ19: DCO3FMMD Index | AR19: DCO3FPML Index | AS19: DCO3FPMS Index | AT19: DCO3FSWL Index | AU19: DCO3FSWS Index | AV19: DCO3FSWD Index | AW19: DCO3FORL Index | AX19: DCO3FORS Index | AY19: DCO3FORD Index | BK19: =A19 -> 17
A20: 18 | B20: OIL- NYM BUTANE | C20: DAE1 Comdty | D20: =_xll.BDH(Tickers!$C20,"px_last",[1]Futures!$A$9,[1]Futures!$A$9,"days=all") -> #NAME? | E20: =_xll.BDP(C20,"QUOTE_UNITS") -> #NAME? | F20: =_xll.BDP(C20,"FUT_CONT_SIZE") -> #NAME? | G20: CFF3BNCL Index | H20: CFF3BNCS Index | I20: CFF3BNCP Index | J20: CFF3BCOL Index | K20: CFF3BCOS Index | L20: CFF3BTLL Index | M20: CFF3BTLS Index | N20: CFF3BOIN Index | O20: CFF3BNRL Index | P20: CFF3BNRS Index | Q20: DFU3GMML Index | R20: DFU3GMMS Index | S20: DFU3GPML Index | T20: DFU3GPMS Index | U20: DFU3GSWL Index | V20: DFU3GSWS Index | W20: DFU3GSWD Index | X20: DFU3GMMD Index | Y20: DFU3GORL Index | Z20: DFU3GORS Index | AA20: DFU3GORD Index | AB20: CFF3BNCN Index | AE20: CFO3BNCL Index | AF20: CFO3BNCS Index | AG20: CFO3BNCP Index | AH20: CFO3BCOL Index | AI20: CFO3BCOS Index | AJ20: CFO3BTLL Index | AK20: CFO3BTLS Index | AL20: CFO3BOIN Index | AM20: CFO3BNRL Index | AN20: CFO3BNRS Index | AO20: DCO3GMML Index | AP20: DCO3GMMS Index | AQ20: DCO3GMMD Index | AR20: DCO3GPML Index | AS20: DCO3GPMS Index | AT20: DCO3GSWL Index | AU20: DCO3GSWS Index | AV20: DCO3GSWD Index | AW20: DCO3GORL Index | AX20: DCO3GORS Index | AY20: DCO3GORD Index | BK20: =A20 -> 18
A21: 19 | B21: OIL - NYM - GASOLINE OPIS | C21: MMB1 Comdty | D21: =_xll.BDH(Tickers!$C21,"px_last",[1]Futures!$A$9,[1]Futures!$A$9,"days=all") -> #NAME? | E21: =_xll.BDP(C21,"QUOTE_UNITS") -> #NAME? | F21: =_xll.BDP(C21,"FUT_CONT_SIZE") -> #NAME? | G21: CFF3CNCL Index | H21: CFF3CNCS Index | I21: CFF3CNCP Index | J21: CFF3CCOL Index | K21: CFF3CCOS Index | L21: CFF3CTLL Index | M21: CFF3CTLS Index | N21: CFF3COIN Index | O21: CFF3CNRL Index | P21: CFF3CNRS Index | Q21: DFU3HMML Index | R21: DFU3HMMS Index | S21: DFU3HPML Index | T21: DFU3HPMS Index | U21: DFU3HSWL Index | V21: DFU3HSWS Index | W21: DFU3HSWD Index | X21: DFU3HMMD Index | Y21: DFU3HORL Index | Z21: DFU3HORS Index | AA21: DFU3HORD Index | AB21: CFF3CNCN Index | AE21: CFO3CNCL Index | AF21: CFO3CNCS Index | AG21: CFO3CNCP Index | AH21: CFO3CCOL Index | AI21: CFO3CCOS Index | AJ21: CFO3CTLL Index | AK21: CFO3CTLS Index | AL21: CFO3COIN Index | AM21: CFO3CNRL Index | AN21: CFO3CNRS Index | AO21: DCO3HMML Index | AP21: DCO3HMMS Index | AQ21: DCO3HMMD Index | AR21: DCO3HPML Index | AS21: DCO3HPMS Index | AT21: DCO3HSWL Index | AU21: DCO3HSWS Index | AV21: DCO3HSWD Index | AW21: DCO3HORL Index | AX21: DCO3HORS Index | AY21: DCO3HORD Index | BK21: =A21 -> 19
A22: 20 | B22: OIL - ICE EUROPE BRENT CRUDE | C22: CO1 COMDTY | D22: =_xll.BDH(Tickers!$C22,"px_last",[1]Futures!$A$9,[1]Futures!$A$9,"days=all") -> #NAME? | E22: USD/bbl. | F22: =_xll.BDP(C22,"FUT_CONT_SIZE") -> #NAME? | N22: ICFUBOIN Index | O22: ICFUBNRL Index | P22: ICFUBNRS Index | Q22: ICFUBMML Index | R22: ICFUBMMS Index | S22: ICFUBPML Index | T22: ICFUBPMS Index | U22: ICFUBSWL Index | V22: ICFUBSWS Index | W22: ICFUBSWD Index | X22: ICFUBMMD Index | Y22: ICFUBORL Index | Z22: ICFUBORS Index | AA22: ICFUBORD Index | AL22: ICCBBOIN Index | AM22: ICCBBNRL Index | AN22: ICCBBNRS Index | AO22: ICCBBMML Index | AP22: ICCBBMMS Index | AQ22: ICCBBMMD Index | AR22: ICCBBPML Index | AS22: ICCBBPMS Index | AT22: ICCBBSWL Index | AU22: ICCBBSWS Index | AV22: ICCBBSWD Index | AW22: ICCBBORL Index | AX22: ICCBBORS Index | AY22: ICCBBORD Index | BK22: =A22 -> 20
A23: 21 | B23: OIL - NYM HEATING OIL | C23: HO1 Comdty | D23: =_xll.BDH(Tickers!$C23,"px_last",[1]Futures!$A$9,[1]Futures!$A$9,"days=all") -> #NAME? | E23: =_xll.BDP(C23,"QUOTE_UNITS") -> #NAME? | F23: =_xll.BDP(C23,"FUT_CONT_SIZE")/100 -> #NAME? | G23: NYM1HNCL Index | H23: NYM1HNCS Index | I23: NYM1HNCP Index | J23: NYM1HCOL Index | K23: NYM1HCOS Index | L23: NYM1HTLL Index | M23: NYM1HTLS Index | N23: NYM1HOIN Index | O23: NYM1HNRL Index | P23: NYM1HNRS Index | Q23: CFFDNMML Index | R23: CFFDNMMS Index | S23: CFFDNPML Index | T23: CFFDNPMS Index | U23: CFFDNSWL Index | V23: CFFDNSWS Index | W23: CFFDNSWD Index | X23: CFFDNMMD Index | Y23: CFFDNORL Index | Z23: CFFDNORS Index | AA23: CFFDNORD Index | AB23: NYM1HNCN Index | AE23: NYMOHNCL Index | AF23: NYMOHNCS Index | AG23: NYMOHNCP Index | AH23: NYMOHCOL Index | AI23: NYMOHCOS Index | AJ23: NYMOHTLL Index | AK23: NYMOHTLS Index | AL23: NYMOHOIN Index | AM23: NYMOHNRL Index | AN23: NYMOHNRS Index | AO23: CFCDNMML Index | AP23: CFCDNMMS Index | AQ23: CFCDNMMD Index | AR23: CFCDNPML Index | AS23: CFCDNPMS Index | AT23: CFCDNSWL Index | AU23: CFCDNSWS Index | AV23: CFCDNSWD Index | AW23: CFCDNORL Index | AX23: CFCDNORS Index | AY23: CFCDNORD Index | BK23: =A23 -> 21
A24: 22 | B24: OIL - ICE EUROPE GASOIL FUTURES | C24: QS1 COMDTY | D24: =_xll.BDH(Tickers!$C24,"px_last",[1]Futures!$A$9,[1]Futures!$A$9,"days=all") -> #NAME? | E24: =_xll.BDP(C24,"QUOTE_UNITS") -> #NAME? | F24: =_xll.BDP(C24,"FUT_CONT_SIZE") -> #NAME? | N24: ICFUAOIN INDEX | O24: ICFUANRL Index | P24: ICFUANRS Index | Q24: ICFUAMML INDEX | R24: ICFUAMMS INDEX | S24: ICFUAPML INDEX | T24: ICFUAPMS INDEX | U24: ICFUASWL INDEX | V24: ICFUASWS INDEX | W24: ICFUASWD INDEX | X24: ICFUAMMD INDEX | Y24: ICFUAORL INDEX | Z24: ICFUAORS INDEX | AA24: ICFUAORD INDEX | AB24: ICFUAORN INDEX | AL24: ICCBAOIN INDEX | AM24: ICCBANRL Index | AN24: ICCBANRS Index | AO24: ICCBAMML Index | AP24: ICCBAMMS Index | AQ24: ICCBAMMD Index | AR24: ICCBAPML INDEX | AS24: ICCBAPMS INDEX | AT24: ICCBASWL INDEX | AU24: ICCBASWS INDEX | AV24: ICCBASWD INDEX | AW24: ICCBAORL INDEX | AX24: ICCBAORS INDEX | AY24: ICCBAORD INDEX | BK24: =A24 -> 22
A25: 23 | B25: OIL - ICE NATURAL GAS HENRY HUB | C25: NR1 COMDTY | D25: =_xll.BDH(Tickers!$C25,"px_last",[1]Futures!$A$9,[1]Futures!$A$9,"days=all") -> #NAME? | E25: =_xll.BDP(C25,"QUOTE_UNITS") -> #NAME? | F25: =_xll.BDP(C25,"FUT_CONT_SIZE") -> #NAME? | G25: EN1FBNCL Index | H25: EN1FBNCS Index | I25: EN1FBNCP Index | J25: EN1FBCOL Index | K25: EN1FBCOS Index | L25: EN1FBTLL Index | M25: EN1FBTLS Index | N25: EN1FBOIN Index | O25: EN1FBNRL Index | P25: EN1FBNRS Index | Q25: DFU4NMML Index | R25: DFU4NMMS Index | S25: DFU4NPML Index | T25: DFU4NPMS Index | U25: DFU4NSWL Index | V25: DFU4NSWS Index | W25: DFU4NSWD Index | X25: DFU4NMMD Index | Y25: DFU4NORL Index | Z25: DFU4NORS Index | AA25: DFU4NORD Index | AB25: EN1FBNCN Index | AE25: EN1CBNCL Index | AF25: EN1CBNCS Index | AG25: EN1CBNCP Index | AH25: EN1CBCOL Index | AI25: EN1CBCOS Index | AJ25: EN1CBTLL Index | AK25: EN1CBTLS Index | AL25: EN1CBOIN Index | AM25: EN1CBNRL Index | AN25: EN1CBNRS Index | AO25: DCO4NMML Index | AP25: DCO4NMMS Index | AQ25: DCO4NMMD Index | AR25: DCO4NPML Index | AS25: DCO4NPMS Index | AT25: DCO4NSWL Index | AU25: DCO4NSWS Index | AV25: DCO4NSWD Index | AW25: DCO4NORL Index | AX25: DCO4NORS Index | AY25: DCO4NORD Index | BK25: =A25 -> 23
A26: 24 | B26: OIL - CRUDE OIL, LIGHT SWEET | C26: EN1 COMDTY | D26: =_xll.BDH(Tickers!$C26,"px_last",[1]Futures!$A$9,[1]Futures!$A$9,"days=all") -> #NAME? | E26: =_xll.BDP(C26,"QUOTE_UNITS") -> #NAME? | F26: =_xll.BDP(C26,"FUT_CONT_SIZE") -> #NAME? | G26: EN1FANCL Index | H26: EN1FANCS Index | I26: EN1FANCP Index | J26: EN1FACOL Index | K26: EN1FACOS Index | L26: EN1FATLL Index | M26: EN1FATLS Index | N26: EN1FAOIN Index | O26: EN1FANRL Index | P26: EN1FANRS Index | Q26: CFFDPMML Index | R26: CFFDPMMS Index | S26: CFFDPPML Index | T26: CFFDPPMS Index | U26: CFFDPSWL Index | V26: CFFDPSWS Index | W26: CFFDPSWD Index | X26: CFFDPMMD Index | Y26: CFFDPORL Index | Z26: CFFDPORS Index | AA26: CFFDPORD Index | AB26: EN1FANCN Index | AE26: EN1CANCL Index | AF26: EN1CANCS Index | AG26: EN1CANCP Index | AH26: EN1CACOL Index | AI26: EN1CACOS Index | AJ26: EN1CATLL Index | AK26: EN1CATLS Index | AL26: EN1CAOIN Index | AM26: EN1CANRL Index | AN26: EN1CANRS Index | AO26: CFCDPMML Index | AP26: CFCDPMMS Index | AQ26: CFCDPMMD Index | AR26: CFCDPPML Index | AS26: CFCDPPMS Index | AT26: CFCDPSWL Index | AU26: CFCDPSWS Index | AV26: CFCDPSWD Index | AW26: CFCDPORL Index | AX26: CFCDPORS Index | AY26: CFCDPORD Index | BK26: =A26 -> 24
A27: 25 | B27: METALS - CMX GOLD | C27: GC1 Comdty | D27: =_xll.BDH(Tickers!$C27,"px_last",[1]Futures!$A$9,[1]Futures!$A$9,"days=all") -> #NAME? | E27: =_xll.BDP(C27,"QUOTE_UNITS") -> #NAME? | F27: =_xll.BDP(C27,"FUT_CONT_SIZE") -> #NAME? | G27: CEI1GNCL Index | H27: CEI1GNCS Index | I27: CEI1GNCP Index | J27: CEI1GCOL Index | K27: CEI1GCOS Index | L27: CEI1GTLL Index | M27: CEI1GTLS Index | N27: CEI1GOIN Index | O27: CEI1GNRL Index | P27: CEI1GNRS Index | Q27: CFFDUMML Index | R27: CFFDUMMS Index | S27: CFFDUPML Index | T27: CFFDUPMS Index | U27: CFFDUSWL Index | V27: CFFDUSWS Index | W27: CFFDUSWD Index | X27: CFFDUMMD Index | Y27: CFFDUORL Index | Z27: CFFDUORS Index | AA27: CFFDUORD Index | AB27: CEI1GNCN Index | AE27: CMXOGNCL Index | AF27: CMXOGNCS Index | AG27: CMXOGNCP Index | AH27: CMXOGCOL Index | AI27: CMXOGCOS Index | AJ27: CMXOGTLL Index | AK27: CMXOGTLS Index | AL27: CMXOGOIN Index | AM27: CMXOGNRL Index | AN27: CMXOGNRS Index | AO27: CFCDUMML Index | AP27: CFCDUMMS Index | AQ27: CFCDUMMD Index | AR27: CFCDUPML Index | AS27: CFCDUPMS Index | AT27: CFCDUSWL Index | AU27: CFCDUSWS Index | AV27: CFCDUSWD Index | AW27: CFCDUORL Index | AX27: CFCDUORS Index | AY27: CFCDUORD Index | BK27: =A27 -> 25
A28: 26 | B28: METALS - CMX SILVER | C28: SI1 Comdty | D28: =_xll.BDH(Tickers!$C28,"px_last",[1]Futures!$A$9,[1]Futures!$A$9,"days=all") -> #NAME? | E28: =_xll.BDP(C28,"QUOTE_UNITS") -> #NAME? | F28: =_xll.BDP(C28,"FUT_CONT_SIZE") -> #NAME? | G28: CEI1SNCL Index | H28: CEI1SNCS Index | I28: CEI1SNCP Index | J28: CEI1SCOL Index | K28: CEI1SCOS Index | L28: CEI1STLL Index | M28: CEI1STLS Index | N28: CEI1SOIN Index | O28: CEI1SNRL Index | P28: CEI1SNRS Index | Q28: CFFDSMML Index | R28: CFFDSMMS Index | S28: CFFDSPML Index | T28: CFFDSPMS Index | U28: CFFDSSWL Index | V28: CFFDSSWS Index | W28: CFFDSSWD Index | X28: CFFDSMMD Index | Y28: CFFDSORL Index | Z28: CFFDSORS Index | AA28: CFFDSORD Index | AB28: CEI1SNCN Index | AE28: CMXOSNCL Index | AF28: CMXOSNCS Index | AG28: CMXOSNCP Index | AH28: CMXOSCOL Index | AI28: CMXOSCOS Index | AJ28: CMXOSTLL Index | AK28: CMXOSTLS Index | AL28: CMXOSOIN Index | AM28: CMXOSNRL Index | AN28: CMXOSNRS Index | AO28: CFCDSMML Index | AP28: CFCDSMMS Index | AQ28: CFCDSMMD Index | AR28: CFCDSPML Index | AS28: CFCDSPMS Index | AT28: CFCDSSWL Index | AU28: CFCDSSWS Index | AV28: CFCDSSWD Index | AW28: CFCDSORL Index | AX28: CFCDSORS Index | AY28: CFCDSORD Index | BK28: =A28 -> 26
A29: 27 | B29: METALS - CMX PLATINUM | C29: PL1 Comdty | D29: =_xll.BDH(Tickers!$C29,"px_last",[1]Futures!$A$9,[1]Futures!$A$9,"days=all") -> #NAME? | E29: =_xll.BDP(C29,"QUOTE_UNITS") -> #NAME? | F29: =_xll.BDP(C29,"FUT_CONT_SIZE") -> #NAME? | G29: NYM3PNCL Index | H29: NYM3PNCS Index | I29: NYM3PNCP Index | J29: NYM3PCOL Index | K29: NYM3PCOS Index | L29: NYM3PTLL Index | M29: NYM3PTLS Index | N29: NYM3POIN Index | O29: NYM3PNRL Index | P29: NYM3PNRS Index | Q29: DFU3OMML Index | R29: DFU3OMMS Index | S29: DFU3OPML Index | T29: DFU3OPMS Index | U29: DFU3OSWL Index | V29: DFU3OSWS Index | W29: DFU3OSWD Index | X29: DFU3OMMD Index | Y29: DFU3OORL Index | Z29: DFU3OORS Index | AA29: DFU3OORD Index | AB29: NYM3PNCN Index | AE29: NYMOPNCL Index | AF29: NYMOPNCS Index | AG29: NYMOPNCP Index | AH29: NYMOPCOL Index | AI29: NYMOPCOS Index | AJ29: NYMOPTLL Index | AK29: NYMOPTLS Index | AL29: NYMOPOIN Index | AM29: NYMOPNRL Index | AN29: NYMOPNRS Index | AO29: DCO3OMML Index | AP29: DCO3OMMS Index | AQ29: DCO3OMMD Index | AR29: DCO3OPML Index | AS29: DCO3OPMS Index | AT29: DCO3OSWL Index | AU29: DCO3OSWS Index | AV29: DCO3OSWD Index | AW29: DCO3OORL Index | AX29: DCO3OORS Index | AY29: DCO3OORD Index | BK29: =A29 -> 27
A30: 28 | B30: METALS - CMX PALLADIUM | C30: PA1 Comdty | D30: =_xll.BDH(Tickers!$C30,"px_last",[1]Futures!$A$9,[1]Futures!$A$9,"days=all") -> #NAME? | E30: =_xll.BDP(C30,"QUOTE_UNITS") -> #NAME? | F30: =_xll.BDP(C30,"FUT_CONT_SIZE") -> #NAME? | G30: NYM2PNCL Index | H30: NYM2PNCS Index | I30: NYM2PNCP Index | J30: NYM2PCOL Index | K30: NYM2PCOS Index | L30: NYM2PTLL Index | M30: NYM2PTLS Index | N30: NYM2POIN Index | O30: NYM2PNRL Index | P30: NYM2PNRS Index | Q30: DFU3NMML Index | R30: DFU3NMMS Index | S30: DFU3NPML Index | T30: DFU3NPMS Index | U30: DFU3NSWL Index | V30: DFU3NSWS Index | W30: DFU3NSWD Index | X30: DFU3NMMD Index | Y30: DFU3NORL Index | Z30: DFU3NORS Index | AA30: DFU3NORD Index | AB30: NYM2PNCN Index | AE30: NYMOANCL Index | AF30: NYMOANCS Index | AG30: NYMOANCP Index | AH30: NYMOACOL Index | AI30: NYMOACOS Index | AJ30: NYMOATLL Index | AK30: NYMOATLS Index | AL30: NYMOAOIN Index | AM30: NYMOANRL Index | AN30: NYMOANRS Index | AO30: DCO3NMML Index | AP30: DCO3NMMS Index | AQ30: DCO3NMMD Index | AR30: DCO3NPML Index | AS30: DCO3NPMS Index | AT30: DCO3NSWL Index | AU30: DCO3NSWS Index | AV30: DCO3NSWD Index | AW30: DCO3NORL Index | AX30: DCO3NORS Index | AY30: DCO3NORD Index | BK30: =A30 -> 28
A31: 29 | B31: METALS - CMX COPPER | C31: HG1 Comdty | D31: =_xll.BDH(Tickers!$C31,"px_last",[1]Futures!$A$9,[1]Futures!$A$9,"days=all") -> #NAME? | E31: =_xll.BDP(C31,"QUOTE_UNITS") -> #NAME? | F31: =_xll.BDP(C31,"FUT_CONT_SIZE")/100 -> #NAME? | G31: CEI1CNCL Index | H31: CEI1CNCS Index | I31: CEI1CNCP Index | J31: CEI1CCOL Index | K31: CEI1CCOS Index | L31: CEI1CTLL Index | M31: CEI1CTLS Index | N31: CEI1COIN Index | O31: CEI1CNRL Index | P31: CEI1CNRS Index | Q31: CFFDTMML Index | R31: CFFDTMMS Index | S31: CFFDTPML Index | T31: CFFDTPMS Index | U31: CFFDTSWL Index | V31: CFFDTSWS Index | W31: CFFDTSWD Index | X31: CFFDTMMD Index | Y31: CFFDTORL Index | Z31: CFFDTORS Index | AA31: CFFDTORD Index | AB31: CEI1CNCN Index | AE31: CMXOCNCL Index | AF31: CMXOCNCS Index | AG31: CMXOCNCP Index | AH31: CMXOCCOL Index | AI31: CMXOCCOS Index | AJ31: CMXOCTLL Index | AK31: CMXOCTLS Index | AL31: CMXOCOIN Index | AM31: CMXOCNRL Index | AN31: CMXOCNRS Index | AO31: CFCDTMML Index | AP31: CFCDTMMS Index | AQ31: CFCDTMMD Index | AR31: CFCDTPML Index | AS31: CFCDTPMS Index | AT31: CFCDTSWL Index | AU31: CFCDTSWS Index | AV31: CFCDTSWD Index | AW31: CFCDTORL Index | AX31: CFCDTORS Index | AY31: CFCDTORD Index | BK31: =A31 -> 29
A32: 30 | B32: SOFTS - ICE COTTON N2 | C32: CT1 Comdty | D32: =_xll.BDH(Tickers!$C32,"px_last",[1]Futures!$A$9,[1]Futures!$A$9,"days=all") -> #NAME? | E32: =_xll.BDP(C32,"QUOTE_UNITS") -> #NAME? | F32: =_xll.BDP(C32,"FUT_CONT_SIZE")/100 -> #NAME? | G32: NYC1CNCL Index | H32: NYC1CNCS Index | I32: NYC1CNCP Index | J32: NYC1CCOL Index | K32: NYC1CCOS Index | L32: NYC1CTLL Index | M32: NYC1CTLS Index | N32: NYC1COIN Index | O32: NYC1CNRL Index | P32: NYC1CNRS Index | Q32: CFFDJMML Index | R32: CFFDJMMS Index | S32: CFFDJPML Index | T32: CFFDJPMS Index | U32: CFFDJSWL Index | V32: CFFDJSWS Index | W32: CFFDJSWD Index | X32: CFFDJMMD Index | Y32: CFFDJORL Index | Z32: CFFDJORS Index | AA32: CFFDJORD Index | AB32: NYC1CNCN Index | AC32: NYCOCCIL Index | AD32: NYCOCCIS Index | AE32: NYCOCNCL Index | AF32: NYCOCNCS Index | AG32: NYCOCNCP Index | AH32: NYCOCCOL Index | AI32: NYCOCCOS Index | AJ32: NYCOCTLL Index | AK32: NYCOCTLS Index | AL32: NYCOCOIN Index | AM32: NYCOCNRL Index | AN32: NYCOCNRS Index | AO32: CFCDJMML Index | AP32: CFCDJMMS Index | AQ32: CFCDJMMD Index | AR32: CFCDJPML Index | AS32: CFCDJPMS Index | AT32: CFCDJSWL Index | AU32: CFCDJSWS Index | AV32: CFCDJSWD Index | AW32: CFCDJORL Index | AX32: CFCDJORS Index | AY32: CFCDJORD Index | AZ32: NYCOCOIN Index | BA32: NYCOCNCL Index | BB32: NYCOCNCS Index | BC32: NYCOCNCP Index | BD32: NYCOCNCN Index | BE32: NYCOCCOL Index | BF32: NYCOCCOS Index | BG32: NYCOCCON Index | BH32: NYCOCNRL Index | BI32: NYCOCNRS Index | BJ32: NYCOCNRN Index | BK32: =A32 -> 30
A33: 31 | B33: SOFTS - ICE COFFEE C | C33: KC1 Comdty | D33: =_xll.BDH(Tickers!$C33,"px_last",[1]Futures!$A$9,[1]Futures!$A$9,"days=all") -> #NAME? | E33: =_xll.BDP(C33,"QUOTE_UNITS") -> #NAME? | F33: =_xll.BDP(C33,"FUT_CONT_SIZE")/100 -> #NAME? | G33: CSC1FNCL Index | H33: CSC1FNCS Index | I33: CSC1FNCP Index | J33: CSC1FCOL Index | K33: CSC1FCOS Index | L33: CSC1FTLL Index | M33: CSC1FTLS Index | N33: CSC1FOIN Index | O33: CSC1FNRL Index | P33: CSC1FNRS Index | Q33: CFFDMMML Index | R33: CFFDMMMS Index | S33: CFFDMPML Index | T33: CFFDMPMS Index | U33: CFFDMSWL Index | V33: CFFDMSWS Index | W33: CFFDMSWD Index | X33: CFFDMMMD Index | Y33: CFFDMORL Index | Z33: CFFDMORS Index | AA33: CFFDMORD Index | AB33: CSC1FNCN Index | AC33: CSCOFCIL Index | AD33: CSCOFCIS Index | AE33: CSCOFNCL Index | AF33: CSCOFNCS Index | AG33: CSCOFNCP Index | AH33: CSCOFCOL Index | AI33: CSCOFCOS Index | AJ33: CSCOFTLL Index | AK33: CSCOFTLS Index | AL33: CSCOFOIN Index | AM33: CSCOFNRL Index | AN33: CSCOFNRS Index | AO33: CFCDMMML Index | AP33: CFCDMMMS Index | AQ33: CFCDMMMD Index | AR33: CFCDMPML Index | AS33: CFCDMPMS Index | AT33: CFCDMSWL Index | AU33: CFCDMSWS Index | AV33: CFCDMSWD Index | AW33: CFCDMORL Index | AX33: CFCDMORS Index | AY33: CFCDMORD Index | AZ33: CSCOFOIN Index | BA33: CSCOFNCL Index | BB33: CSCOFNCS Index | BC33: CSCOFNCP Index | BD33: CSCOFNCN Index | BE33: CSCOFCOL Index | BF33: CSCOFCOS Index | BG33: CSCOFCON Index | BH33: CSCOFNRL Index | BI33: CSCOFNRS Index | BJ33: CSCOFNRN Index | BK33: =A33 -> 31
A34: 32 | B34: SOFTS - ICE SUGAR N11 | C34: SB1 Comdty | D34: =_xll.BDH(Tickers!$C34,"px_last",[1]Futures!$A$9,[1]Futures!$A$9,"days=all") -> #NAME? | E34: =_xll.BDP(C34,"QUOTE_UNITS") -> #NAME? | F34: =_xll.BDP(C34,"FUT_CONT_SIZE")/100 -> #NAME? | G34: CSC1SNCL Index | H34: CSC1SNCS Index | I34: CSC1SNCP Index | J34: CSC1SCOL Index | K34: CSC1SCOS Index | L34: NYM1ETLL Index | M34: NYM1ETLS Index | N34: CSC1SOIN Index | O34: CSC1SNRL Index | P34: CSC1SNRS Index | Q34: CFFDLMML Index | R34: CFFDLMMS Index | S34: CFFDLPML Index | T34: CFFDLPMS Index | U34: CFFDLSWL Index | V34: CFFDLSWS Index | W34: CFFDLSWD Index | X34: CFFDLMMD Index | Y34: CFFDLORL Index | Z34: CFFDLORS Index | AA34: CFFDLORD Index | AB34: CSC1SNCN Index | AC34: CSCOSCIL Index | AD34: CSCOSCIS Index | AE34: CSCOSNCL Index | AF34: CSCOSNCS Index | AG34: CSCOSNCP Index | AH34: CSCOSCOL Index | AI34: CSCOSCOS Index | AJ34: CSCOSTLL Index | AK34: CSCOSTLS Index | AL34: CSCOSOIN Index | AM34: CSCOSNRL Index | AN34: CSCOSNRS Index | AO34: CFCDLMML Index | AP34: CFCDLMMS Index | AQ34: CFCDLMMD Index | AR34: CFCDLPML Index | AS34: CFCDLPMS Index | AT34: CFCDLSWL Index | AU34: CFCDLSWS Index | AV34: CFCDLSWD Index | AW34: CFCDLORL Index | AX34: CFCDLORS Index | AY34: CFCDLORD Index | AZ34: CSCOSOIN Index | BA34: CSCOSNCL Index | BB34: CSCOSNCS Index | BC34: CSCOSNCP Index | BD34: CSCOSNCN Index | BE34: CSCOSCOL Index | BF34: CSCOSCOS Index | BG34: CSCOSCON Index | BH34: CSCOSNRL Index | BI34: CSCOSNRS Index | BJ34: CSCOSNRN Index | BK34: =A34 -> 32
A35: 33 | B35: SOFTS - ICE FROZEN ORANGE JUICE | C35: JO1 Comdty | D35: =_xll.BDH(Tickers!$C35,"px_last",[1]Futures!$A$9,[1]Futures!$A$9,"days=all") -> #NAME? | E35: =_xll.BDP(C35,"QUOTE_UNITS") -> #NAME? | F35: =_xll.BDP(C35,"FUT_CONT_SIZE")/100 -> #NAME? | G35: CAN1ONCL Index | H35: CAN1ONCS Index | I35: CAN1ONCP Index | J35: CAN1OCOL Index | K35: CAN1OCOS Index | L35: CAN1OTLL Index | M35: CAN1OTLS Index | N35: CAN1OOIN Index | O35: CAN1ONRL Index | P35: CAN1ONRS Index | Q35: DFU2IMML Index | R35: DFU2IMMS Index | S35: DFU2IPML Index | T35: DFU2IPMS Index | U35: DFU2ISWL Index | V35: DFU2ISWS Index | W35: DFU2ISWD Index | X35: DFU2IMMD Index | Y35: DFU2IORL Index | Z35: DFU2IORS Index | AA35: DFU2IORD Index | AB35: CAN1ONCN Index | AE35: NYCOONCL Index | AF35: NYCOONCS Index | AG35: NYCOONCP Index | AH35: NYCOOCOL Index | AI35: NYCOOCOS Index | AJ35: NYCOOTLL Index | AK35: NYCOOTLS Index | AL35: NYCOOOIN Index | AM35: NYCOONRL Index | AN35: NYCOONRS Index | AO35: DCO2IMML Index | AP35: DCO2IMMS Index | AQ35: DCO2IMMD Index | AR35: DCO2IPML Index | AS35: DCO2IPMS Index | AT35: DCO2ISWL Index | AU35: DCO2ISWS Index | AV35: DCO2ISWD Index | AW35: DCO2IORL Index | AX35: DCO2IORS Index | AY35: DCO2IORD Index | BK35: =A35 -> 33
A36: 34 | B36: SOFTS - ICE COCOA | C36: CC1 Comdty | D36: =_xll.BDH(Tickers!$C36,"px_last",[1]Futures!$A$9,[1]Futures!$A$9,"days=all") -> #NAME? | E36: =_xll.BDP(C36,"QUOTE_UNITS") -> #NAME? | F36: =_xll.BDP(C36,"FUT_CONT_SIZE") -> #NAME? | G36: CSC1CNCL Index | H36: CSC1CNCS Index | I36: CSC1CNCP Index | J36: CSC1CCOL Index | K36: CSC1CCOS Index | L36: CSC1CTLL Index | M36: CSC1CTLS Index | N36: CSC1COIN Index | O36: CSC1CNRL Index | P36: CSC1CNRS Index | Q36: CFFDKMML Index | R36: CFFDKMMS Index | S36: CFFDKPML Index | T36: CFFDKPMS Index | U36: CFFDKSWL Index | V36: CFFDKSWS Index | W36: CFFDKSWD Index | X36: CFFDKMMD Index | Y36: CFFDKORL Index | Z36: CFFDKORS Index | AA36: CFFDKORD Index | AB36: CSC1CNCN Index | AC36: CSCOCCIL Index | AD36: CSCOCCIS Index | AE36: CSCOCNCL Index | AF36: CSCOCNCS Index | AG36: CSCOCNCP Index | AH36: CSCOCCOL Index | AI36: CSCOCCOS Index | AJ36: CSCOCTLL Index | AK36: CSCOCTLS Index | AL36: CSCOCOIN Index | AM36: CSCOCNRL Index | AN36: CSCOCNRS Index | AO36: CFCDKMML Index | AP36: CFCDKMMS Index | AQ36: CFCDKMMD Index | AR36: CFCDKPML Index | AS36: CFCDKPMS Index | AT36: CFCDKSWL Index | AU36: CFCDKSWS Index | AV36: CFCDKSWD Index | AW36: CFCDKORL Index | AX36: CFCDKORS Index | AY36: CFCDKORD Index | AZ36: CSCOCOIN Index | BA36: CSCOCNCL Index | BB36: CSCOCNCS Index | BC36: CSCOCNCP Index | BD36: CSCOCNCN Index | BE36: CSCOCCOL Index | BF36: CSCOCCOS Index | BG36: CSCOCCON Index | BH36: CSCOCNRL Index | BI36: CSCOCNRS Index | BJ36: CSCOCNRN Index | BK36: =A36 -> 34
A37: 35 | B37: SOFTS - NYSE LIFFE COCOA | C37: QC1 COMDTY | D37: =_xll.BDH(Tickers!$C37,"px_last",[1]Futures!$A$9,[1]Futures!$A$9,"days=all") -> #NAME? | E37: =_xll.BDP(C37,"QUOTE_UNITS") -> #NAME? | F37: =_xll.BDP(C37,"FUT_CONT_SIZE") -> #NAME? | N37: LIFFAOIN Index | O37: LIFFANRL Index | P37: LIFFANRS Index | Q37: DLIFAMML Index | R37: DLIFAMMS Index | S37: DLIFAPML Index | T37: DLIFAPMS Index | U37: DLIFASWL Index | V37: DLIFASWS Index | W37: DLIFASWD Index | X37: DLIFAMMD Index | Y37: DLIFAORL Index | Z37: DLIFAORS Index | AA37: DLIFAORD Index | AL37: LIFCAOIN Index | AM37: LIFCANRL Index | AN37: LIFCANRS Index | AO37: DLICAMML Index | AP37: DLICAMMS Index | AQ37: DLICAMMD Index | AR37: DLICAPML Index | AS37: DLICAPMS Index | AT37: DLICASWL Index | AU37: DLICASWS Index | AV37: DLICASWD Index | AW37: DLICAORL Index | AX37: DLICAORS Index | AY37: DLICAORD Index | BK37: =A37 -> 35
A38: 36 | B38: SOFTS - NYSE LIFFE ROBUSTA COFFE | C38: DF1 COMDTY | D38: =_xll.BDH(Tickers!$C38,"px_last",[1]Futures!$A$9,[1]Futures!$A$9,"days=all") -> #NAME? | E38: =_xll.BDP(C38,"QUOTE_UNITS") -> #NAME? | F38: =_xll.BDP(C38,"FUT_CONT_SIZE") -> #NAME? | N38: LIFFBOIN Index | O38: LIFFBNRL Index | P38: LIFFBNRS Index | Q38: DLIFBMML Index | R38: DLIFBMMS Index | S38: DLIFBPML Index | T38: DLIFBPMS Index | U38: DLIFBSWL Index | V38: DLIFBSWS Index | W38: DLIFBSWD Index | X38: DLIFBMMD Index | Y38: DLIFBORL Index | Z38: DLIFBORS Index | AA38: DLIFBORD Index | AL38: LIFCBOIN Index | AM38: LIFCBNRL Index | AN38: LIFCBNRS Index | AO38: DLICBMML Index | AP38: DLICBMMS Index | AQ38: DLICBMMD Index | AR38: DLICBPML Index | AS38: DLICBPMS Index | AT38: DLICBSWL Index | AU38: DLICBSWS Index | AV38: DLICBSWD Index | AW38: DLICBORL Index | AX38: DLICBORS Index | AY38: DLICBORD Index | BK38: =A38 -> 36
A39: 37 | B39: FX - CME BRITISH POUND STERLING | C39: BP1 CURNCY | D39: =_xll.BDH(Tickers!$C39,"px_last",[1]Futures!$A$9,[1]Futures!$A$9,"days=all") -> #NAME? | E39: =_xll.BDP(C39,"QUOTE_UNITS") -> #NAME? | F39: =_xll.BDP(C39,"FUT_CONT_SIZE")/100 -> #NAME? | G39: IMM5PNCL Index | H39: IMM5PNCS Index | I39: IMM5PNCP Index | J39: IMM5PCOL Index | K39: IMM5PCOS Index | L39: IMM5PTLL Index | M39: IMM5PTLS Index | N39: IMM5POIN Index | O39: IMM5PNRL Index | P39: IMM5PNRS Index | AB39: IMM5PNCN Index | AE39: IMMOPNCL Index | AF39: IMMOPNCS Index | AG39: IMMOPNCP Index | AH39: IMMOPCOL Index | AI39: IMMOPCOS Index | AJ39: IMMOPTLL Index | AK39: IMMOPTLS Index | AL39: IMMOPOIN Index | AM39: IMMOPNRL Index | AN39: IMMOPNRS Index | BK39: =A39 -> 37
A40: 38 | B40: FX - CME EURO | C40: EC1 CURNCY | D40: =_xll.BDH(Tickers!$C40,"px_last",[1]Futures!$A$9,[1]Futures!$A$9,"days=all") -> #NAME? | E40: =_xll.BDP(C40,"QUOTE_UNITS") -> #NAME? | F40: =_xll.BDP(C40,"FUT_CONT_SIZE") -> #NAME? | G40: IMMBENCL Index | H40: IMMBENCS Index | I40: IMMBENCP Index | J40: IMMBECOL Index | K40: IMMBECOS Index | L40: IMMBETLL Index | M40: IMMBETLS Index | N40: IMMBEOIN Index | O40: IMMBENRL Index | P40: IMMBENRS Index | AB40: IMMBENCN Index | AE40: IMMPFNCL Index | AF40: IMMPFNCS Index | AG40: IMMPFNCP Index | AH40: IMMPFCOL Index | AI40: IMMPFCOS Index | AJ40: IMMPFTLL Index | AK40: IMMPFTLS Index | AL40: IMMPFOIN Index | AM40: IMMPFNRL Index | AN40: IMMPFNRS Index | BK40: =A40 -> 38
...
